[INFO -- 2018-12-04 02:14:27]
Starting flip_value script
version: 1.1
[INFO -- 2018-12-04 02:14:27]
Initialization strings:
[INFO -- 2018-12-04 02:14:27]
(1) file /home/latansini/carol-fi/carol-fi/codes/nnfulldup/nn-knl-files/nn
[INFO -- 2018-12-04 02:14:27]
(2) set args /home/latansini/carol-fi/carol-fi/codes/nnfulldup/nn-knl-files/filelist 20 5 5 /home/latansini/carol-fi/carol-fi/codes/nnfulldup/nn-knl-files/out20_5_5
[INFO -- 2018-12-04 02:14:27]
initSignal:0
[INFO -- 2018-12-04 02:14:27]
endSignal:2
[INFO -- 2018-12-04 02:14:27]
faultModel:2
[EXCEPTION -- 2018-12-04 02:14:28]
pythonException: invalid frame
[EXCEPTION -- 2018-12-04 02:14:28]
pythonException: invalid frame
[EXCEPTION -- 2018-12-04 02:14:28]
pythonException: invalid frame
[EXCEPTION -- 2018-12-04 02:14:28]
pythonException: invalid frame
[EXCEPTION -- 2018-12-04 02:14:28]
pythonException: invalid frame
[INFO -- 2018-12-04 02:14:28]
Backtrace BEGIN:
#0  0x00007ffff78d4c9e in ?? () from /usr/lib/x86_64-linux-gnu/libgomp.so.1
#1  0x00007ffff78d26f0 in ?? () from /usr/lib/x86_64-linux-gnu/libgomp.so.1
#2  0x00007ffff76b0064 in start_thread (arg=0x7ffff42f6700) at pthread_create.c:309
#3  0x00007ffff73e562d in clone () at ../sysdeps/unix/sysv/linux/x86_64/clone.S:111

4072	in malloc.c

Backtrace END
Fliping array at pos: 8
Memory content before bitflip:0x65
Fault Model: Random bit-flip
base address to flip value: 0x7ffff7461633  
address max offset: 1
Memory content after  bitflip:0xfa
frame name: _int_free
symbol name: __func__
symbol filename: malloc.c
symbol line: 0
value: "_int_fr", <incomplete sequence \372>
value address: 0x7ffff746162b <__func__.11560>
Type: The type is an array.
Type sizeof: 10
Field name: None
Field Type: A range type, that is, an integer type with bounds.
Field Type sizeof: 8
Field Type range: (0L, 9L)

[INFO -- 2018-12-04 02:14:28]
Fault Injection Successful after 1.60999107361s
[INFO -- 2018-12-04 02:14:28]
event type: exit
[EXCEPTION -- 2018-12-04 02:14:28]
exit code: no exit code available
[EXCEPTION -- 2018-12-04 02:14:28]
pythonException: Thread no longer exists.
